---
title: Durable Functions のエラー処理 - Azure
description: Azure Functions の Durable Functions 拡張機能で発生したエラーを処理する方法について説明します。
services: functions
author: kashimiz
manager: jeconnoc
keywords: ''
ms.service: azure-functions
ms.devlang: multiple
ms.topic: conceptual
ms.date: 10/23/2018
ms.author: azfuncdf
ms.openlocfilehash: 61496d91c9ec2cd1dcf498df04d2dab6629e009c
ms.sourcegitcommit: c2c279cb2cbc0bc268b38fbd900f1bac2fd0e88f
ms.translationtype: HT
ms.contentlocale: ja-JP
ms.lasthandoff: 10/24/2018
ms.locfileid: "49984130"
---
# <a name="handling-errors-in-durable-functions-azure-functions"></a>Durable Functions のエラー処理 (Azure Functions)

Durable Function のオーケストレーションはコードで実装され、プログラミング言語のエラー処理機能を使用できます。 この点を考慮すると、エラー処理と補正をオーケストレーションに組み込むときに知っておく必要がある新しい概念は実際にはありません。 ただし、注意する必要があるいくつかの動作があります。

## <a name="errors-in-activity-functions"></a>アクティビティ関数のエラー

アクティビティ関数でスローされた例外はオーケストレーター関数に戻され、`FunctionFailedException` としてスローされます。 ニーズに合ったエラー処理と補正コードをオーケストレーター関数内に記述できます。

たとえば、ある口座の資金を別の口座に送金する次のオーケストレーター関数を検討します。

#### <a name="c"></a>C#

```csharp
#r "Microsoft.Azure.WebJobs.Extensions.DurableTask"

public static async Task Run(DurableOrchestrationContext context)
{
    var transferDetails = ctx.GetInput<TransferOperation>();

    await context.CallActivityAsync("DebitAccount",
        new
        { 
            Account = transferDetails.SourceAccount,
            Amount = transferDetails.Amount
        });

    try
    {
        await context.CallActivityAsync("CreditAccount",         
            new
            { 
                Account = transferDetails.DestinationAccount,
                Amount = transferDetails.Amount
            });
    }
    catch (Exception)
    {
        // Refund the source account.
        // Another try/catch could be used here based on the needs of the application.
        await context.CallActivityAsync("CreditAccount",         
            new
            { 
                Account = transferDetails.SourceAccount,
                Amount = transferDetails.Amount
            });
    }
}
```

#### <a name="javascript-functions-v2-only"></a>JavaScript (Functions v2 のみ)

```javascript
const df = require("durable-functions");

module.exports = df.orchestrator(function*(context) {
    const transferDetails = context.df.getInput();

    yield context.df.callActivity("DebitAccount",
        {
            account = transferDetails.sourceAccount,
            amount = transferDetails.amount,
        }
    );

    try {
        yield context.df.callActivity("CreditAccount",
            {
                account = transferDetails.destinationAccount,
                amount = transferDetails.amount,
            }
        );
    }
    catch (error) {
        // Refund the source account.
        // Another try/catch could be used here based on the needs of the application.
        yield context.df.callActivity("CreditAccount",
            {
                account = transferDetails.sourceAccount,
                amount = transferDetails.amount,
            }
        );
    }
});
```

送金先口座に対する **CreditAccount** 関数の呼び出しが失敗した場合、オーケストレーター関数は、資金を送金元口座に戻すことで、これを補正します。

## <a name="automatic-retry-on-failure"></a>エラー発生時の自動再試行

アクティビティ関数またはサブオーケストレーション関数を呼び出すときに、自動再試行ポリシーを指定できます。 次の例では、関数の呼び出しを最大 3 回試行し、次の再試行まで 5 秒間待機します。

#### <a name="c"></a>C#

```csharp
public static async Task Run(DurableOrchestrationContext context)
{
    var retryOptions = new RetryOptions(
        firstRetryInterval: TimeSpan.FromSeconds(5),
        maxNumberOfAttempts: 3);

    await ctx.CallActivityWithRetryAsync("FlakyFunction", retryOptions, null);
    
    // ...
}
```

#### <a name="javascript-functions-v2-only"></a>JavaScript (Functions v2 のみ)

```javascript
const df = require("durable-functions");

module.exports = df.orchestrator(function*(context) {
    const retryOptions = new df.RetryOptions(5000, 3);
    
    yield context.df.callActivityWithRetry("FlakyFunction", retryOptions);

    // ...
});
```

`CallActivityWithRetryAsync` (C#) または `callActivityWithRetry` (JS) API は、`RetryOptions` パラメーターを使用します。 `CallSubOrchestratorWithRetryAsync` (C#) または `callSubOrchestratorWithRetry` (JS) API を使用するサブオーケストレーション呼び出しは、同じ再試行ポリシーを使用できます。

自動再試行ポリシーをカスタマイズするためのいくつかのオプションがあります。 次のオプションが含まれます。

* **最大試行回数**: 再試行が行われる最大回数。
* **1 回目の再試行の間隔**: 1 回目の再試行を行う前の待機時間。
* **バックオフ係数**: バックオフの増加率を決定するために使用される係数。 既定値は 1 です。
* **最大再試行間隔**: 次の再試行を実行する前に待機する最大時間。
* **再試行タイムアウト**: 再試行を実行するために費やす最大時間。 既定の動作は、無限の再試行です。
* **ハンドル**: 関数呼び出しを再試行するかどうかを決定するユーザー定義のコールバックを指定できます。

## <a name="function-timeouts"></a>関数のタイムアウト

完了に時間がかかりすぎる場合は、オーケストレーター関数内の関数呼び出しを破棄できます。 現時点でこれを行う適切な方法は、次の例に示すように、`context.CreateTimer` と `Task.WhenAny` を使用して[永続タイマー](durable-functions-timers.md)を作成することです。

#### <a name="c"></a>C#

```csharp
public static async Task<bool> Run(DurableOrchestrationContext context)
{
    TimeSpan timeout = TimeSpan.FromSeconds(30);
    DateTime deadline = context.CurrentUtcDateTime.Add(timeout);

    using (var cts = new CancellationTokenSource())
    {
        Task activityTask = context.CallActivityAsync("FlakyFunction");
        Task timeoutTask = context.CreateTimer(deadline, cts.Token);

        Task winner = await Task.WhenAny(activityTask, timeoutTask);
        if (winner == activityTask)
        {
            // success case
            cts.Cancel();
            return true;
        }
        else
        {
            // timeout case
            return false;
        }
    }
}
```

#### <a name="javascript-functions-v2-only"></a>JavaScript (Functions v2 のみ)

```javascript
const df = require("durable-functions");
const moment = require("moment");

module.exports = df.orchestrator(function*(context) {
    const deadline = moment.utc(context.df.currentUtcDateTime).add(30, "s");

    const activityTask = context.df.callActivity("FlakyFunction");
    const timeoutTask = context.df.createTimer(deadline.toDate());

    const winner = yield context.df.Task.any([activityTask, timeoutTask]);
    if (winner === activityTask) {
        // success case
        timeoutTask.cancel();
        return true;
    } else {
        // timeout case
        return false;
    }
});
```

> [!NOTE]
> このメカニズムは、実際には、進行中のアクティビティ関数の実行を終了するのではなく、 オーケストレーター関数が、単に結果を無視して、次に進めるようにするだけです。 詳細については、[タイマー](durable-functions-timers.md#usage-for-timeout)に関するドキュメントをご覧ください。

## <a name="unhandled-exceptions"></a>ハンドルされない例外

オーケストレーター関数がハンドルされない例外で失敗した場合、例外の詳細がログに記録され、インスタンスは `Failed` 状態で完了します。

## <a name="next-steps"></a>次の手順

> [!div class="nextstepaction"]
> [問題を診断する方法を知る](durable-functions-diagnostics.md)
